#### 27. Задача. Какой вывод в консоль. Работа с исключениями в Java и правильно обрабатывать несколько типов исключений, включая наследование исключений (например, FileNotFoundException — это подкласс IOException)


```java
public static void main(String[] args) {
    try {
        throw new RuntimeException(""1"");
    } catch (Exception e) {
        throw new RuntimeException(""2"");
    } finally {
        throw new RuntimeException(""3"");
    }
}

```


{{< hint warning >}}
**Спойлеры к решению**  
{{< /hint >}}

{{< details "Подсказки" close >}}

- **Блок `finally` выполняется всегда**, даже если в `catch` есть `throw`.
- Если в `catch` выбрасывается исключение, а затем в `finally` тоже выбрасывается новое исключение, **исключение из `finally` "затирает" предыдущее**.
- Поэтому исключение `"3"` из `finally` станет окончательным исключением.

{{< /details >}}

{{< details "Решение" close >}}
Код вызывает `RuntimeException("1")`, который ловится `catch (Exception e)`, затем выбрасывается `RuntimeException("2")`.  
Но `finally` тоже выбрасывает `RuntimeException("3")`, из-за чего `"2"` теряется.

Вывод в консоль:

```
Exception in thread "main" java.lang.RuntimeException: 3
	at Main.main(Main.java:9)
```
{{< /details >}}